{
 "cells": [
  {
   "cell_type": "code",
   "execution_count": 12,
   "id": "800e7378",
   "metadata": {},
   "outputs": [],
   "source": [
    "import asyncio"
   ]
  },
  {
   "cell_type": "code",
   "execution_count": 13,
   "id": "539fb49f",
   "metadata": {},
   "outputs": [],
   "source": [
    "async def task():\n",
    "    print('long time task')\n",
    "    await asyncio.sleep(2)\n",
    "    print('task complete')"
   ]
  },
  {
   "cell_type": "code",
   "execution_count": 14,
   "id": "280c8e68",
   "metadata": {},
   "outputs": [
    {
     "ename": "RuntimeError",
     "evalue": "asyncio.run() cannot be called from a running event loop",
     "output_type": "error",
     "traceback": [
      "\u001b[1;31m---------------------------------------------------------------------------\u001b[0m",
      "\u001b[1;31mRuntimeError\u001b[0m                              Traceback (most recent call last)",
      "\u001b[1;32mC:\\Users\\SANTIA~1\\AppData\\Local\\Temp/ipykernel_27592/2224048870.py\u001b[0m in \u001b[0;36m<module>\u001b[1;34m\u001b[0m\n\u001b[1;32m----> 1\u001b[1;33m \u001b[0masyncio\u001b[0m\u001b[1;33m.\u001b[0m\u001b[0mrun\u001b[0m\u001b[1;33m(\u001b[0m\u001b[0mtask\u001b[0m\u001b[1;33m(\u001b[0m\u001b[1;33m)\u001b[0m\u001b[1;33m)\u001b[0m\u001b[1;33m\u001b[0m\u001b[1;33m\u001b[0m\u001b[0m\n\u001b[0m",
      "\u001b[1;32m~\\anaconda3\\lib\\asyncio\\runners.py\u001b[0m in \u001b[0;36mrun\u001b[1;34m(main, debug)\u001b[0m\n\u001b[0;32m     31\u001b[0m     \"\"\"\n\u001b[0;32m     32\u001b[0m     \u001b[1;32mif\u001b[0m \u001b[0mevents\u001b[0m\u001b[1;33m.\u001b[0m\u001b[0m_get_running_loop\u001b[0m\u001b[1;33m(\u001b[0m\u001b[1;33m)\u001b[0m \u001b[1;32mis\u001b[0m \u001b[1;32mnot\u001b[0m \u001b[1;32mNone\u001b[0m\u001b[1;33m:\u001b[0m\u001b[1;33m\u001b[0m\u001b[1;33m\u001b[0m\u001b[0m\n\u001b[1;32m---> 33\u001b[1;33m         raise RuntimeError(\n\u001b[0m\u001b[0;32m     34\u001b[0m             \"asyncio.run() cannot be called from a running event loop\")\n\u001b[0;32m     35\u001b[0m \u001b[1;33m\u001b[0m\u001b[0m\n",
      "\u001b[1;31mRuntimeError\u001b[0m: asyncio.run() cannot be called from a running event loop"
     ]
    }
   ],
   "source": [
    "asyncio.run(task())"
   ]
  },
  {
   "cell_type": "markdown",
   "id": "92f1be02",
   "metadata": {},
   "source": [
    "[Error reference and solution](https://stackoverflow.com/questions/55409641/asyncio-run-cannot-be-called-from-a-running-event-loop)"
   ]
  },
  {
   "cell_type": "code",
   "execution_count": 15,
   "id": "2f2ea47f",
   "metadata": {},
   "outputs": [
    {
     "name": "stdout",
     "output_type": "stream",
     "text": [
      "long time task\n",
      "task complete\n"
     ]
    }
   ],
   "source": [
    "await task()"
   ]
  },
  {
   "cell_type": "code",
   "execution_count": null,
   "id": "b4295e8a",
   "metadata": {},
   "outputs": [],
   "source": []
  }
 ],
 "metadata": {
  "kernelspec": {
   "display_name": "Python 3 (ipykernel)",
   "language": "python",
   "name": "python3"
  },
  "language_info": {
   "codemirror_mode": {
    "name": "ipython",
    "version": 3
   },
   "file_extension": ".py",
   "mimetype": "text/x-python",
   "name": "python",
   "nbconvert_exporter": "python",
   "pygments_lexer": "ipython3",
   "version": "3.9.7"
  }
 },
 "nbformat": 4,
 "nbformat_minor": 5
}
